Workbook

Sheet Cover
B2: SEEKING ALPHA ADVISORS
B3: Research, Advisory & Execution
B5: Alpha Legal — Platform Unit Economics
B6: Singapore VCC origination platform · 5-year model
B8: HOW TO USE
B9: 1. Set the two controls on the Assumptions tab: Scenario (Bull / Base / Bear) and Policy (conversion On / Off).
B10: 2. Edit any blue input cell (pricing, costs, scenario drivers) to flex the model.
B11: 3. The Model tab shows the active scenario in detail. Scenarios compares all three plus the policy convexity. Dashboard shows the headline KPIs and chart.
B12: 4. All figures recalculate live. Blue = input, black = formula.
B14: READ THIS
B15: Illustrative model built from public cost ranges, not a forecast. Unit prices and take rates are assumptions; willingness-to-pay is unproven.
B16: The conversion policy (onboarding SG companies / unit trusts to a VCC) is reported as under MAS consideration, not enacted. It is the upside lever, modelled via the Policy toggle.
... B19: a MERE conduit for the VISION · Wallahu a'lam

Sheet Assumptions
B2: ASSUMPTIONS & CONTROLS
B4: CONTROLS
B5: Scenario
B6: Base
B7: Policy: VCC conversion of SG cos / unit trusts
B8: On
B9: Policy flag (auto)
B10: =IF(B8="On",1,0) -> 1
B12: PRICING (S$)
B13: VCC document-set fee (per setup) | C13: 2000
B14: Sub-fund generation fee (per sub-fund) | C14: 500
B15: White-label licence (per firm, per year) | C15: 36000
B16: Recurring orchestration (per active VCC, per year) | C16: 600
B18: COSTS
B19: Fixed opex, Year 1 (dev, hosting, compliance, team) | C19: 450000
B20: Fixed opex growth (per year) | C20: 0.12
B21: Marginal cost per document set | C21: 100
B22: Marginal cost per sub-fund | C22: 30
B23: Active VCC retention (per year) | C23: 0.9
B25: SCENARIO DRIVERS
C26: Bull | D26: Base | E26: Bear | F26: Active
B27: Market new VCCs, Year 1 | C27: 350 | D27: 300 | E27: 250 | F27: =IF($B$6="Bull",C27,IF($B$6="Base",D27,E27)) -> 300
B28: Market growth (per year) | C28: 0.15 | D28: 0.1 | E28: 0.05 | F28: =IF($B$6="Bull",C28,IF($B$6="Base",D28,E28)) -> 0.1
B29: Platform share of new VCCs, Year 1 | C29: 0.05 | D29: 0.03 | E29: 0.02 | F29: =IF($B$6="Bull",C29,IF($B$6="Base",D29,E29)) -> 0.03
B30: Platform share of new VCCs, Year 5 | C30: 0.2 | D30: 0.12 | E30: 0.06 | F30: =IF($B$6="Bull",C30,IF($B$6="Base",D30,E30)) -> 0.12
B31: New sub-funds per active VCC, per year | C31: 0.8 | D31: 0.6 | E31: 0.4 | F31: =IF($B$6="Bull",C31,IF($B$6="Base",D31,E31)) -> 0.6
B32: White-label firms, Year 1 | C32: 5 | D32: 3 | E32: 2 | F32: =IF($B$6="Bull",C32,IF($B$6="Base",D32,E32)) -> 3
B33: White-label firms, Year 5 | C33: 30 | D33: 20 | E33: 10 | F33: =IF($B$6="Bull",C33,IF($B$6="Base",D33,E33)) -> 20
B34: Conversion-eligible base (SG cos / unit trusts) | C34: 12000 | D34: 10000 | E34: 8000 | F34: =IF($B$6="Bull",C34,IF($B$6="Base",D34,E34)) -> 10000
B35: Conversion adoption, per year (of remaining) | C35: 0.03 | D35: 0.02 | E35: 0.01 | F35: =IF($B$6="Bull",C35,IF($B$6="Base",D35,E35)) -> 0.02
B36: Platform share of conversions | C36: 0.12 | D36: 0.08 | E36: 0.04 | F36: =IF($B$6="Bull",C36,IF($B$6="Base",D36,E36)) -> 0.08

Sheet Model
B2: MODEL — ACTIVE SCENARIO
B3: =CONCATENATE("Scenario: ",Assumptions!B6," | Policy: ",Assumptions!B8) -> Scenario: Base | Policy: On
B5: 5-YEAR BUILD
C6: Year 1 | D6: Year 2 | E6: Year 3 | F6: Year 4 | G6: Year 5
B7: Market new VCCs | C7: =Assumptions!F$27 -> 300 | D7: =C7*(1+Assumptions!F$28) -> 330 | E7: =D7*(1+Assumptions!F$28) -> 363 | F7: =E7*(1+Assumptions!F$28) -> 399.3 | G7: =F7*(1+Assumptions!F$28) -> 439.23
B8: Platform share of new VCCs | C8: =Assumptions!F$29 -> 0.03 | D8: =Assumptions!F$29+(Assumptions!F$30-Assumptions!F$29)*1/4 -> 0.0525 | E8: =Assumptions!F$29+(Assumptions!F$30-Assumptions!F$29)*2/4 -> 0.075 | F8: =Assumptions!F$29+(Assumptions!F$30-Assumptions!F$29)*3/4 -> 0.0975 | G8: =Assumptions!F$30 -> 0.12
B9: Platform new VCCs (organic) | C9: =C7*C8 -> 9 | D9: =D7*D8 -> 17.325 | E9: =E7*E8 -> 27.225 | F9: =F7*F8 -> 38.93175 | G9: =G7*G8 -> 52.7076
B10: Conversion eligible (start) | C10: =Assumptions!F$34 -> 10000 | D10: =C10-C11 -> 9800 | E10: =D10-D11 -> 9604 | F10: =E10-E11 -> 9411.92 | G10: =F10-F11 -> 9223.6816
B11: Conversions (policy-gated) | C11: =C10*Assumptions!F$35*Assumptions!$B$10 -> 200 | D11: =D10*Assumptions!F$35*Assumptions!$B$10 -> 196 | E11: =E10*Assumptions!F$35*Assumptions!$B$10 -> 192.08 | F11: =F10*Assumptions!F$35*Assumptions!$B$10 -> 188.2384 | G11: =G10*Assumptions!F$35*Assumptions!$B$10 -> 184.47363
B12: Platform conversions | C12: =C11*Assumptions!F$36 -> 16 | D12: =D11*Assumptions!F$36 -> 15.68 | E12: =E11*Assumptions!F$36 -> 15.3664 | F12: =F11*Assumptions!F$36 -> 15.059072 | G12: =G11*Assumptions!F$36 -> 14.757891
B13: Platform new VCCs (total) | C13: =C9+C12 -> 25 | D13: =D9+D12 -> 33.005 | E13: =E9+E12 -> 42.5914 | F13: =F9+F12 -> 53.990822 | G13: =G9+G12 -> 67.465491
B14: Active platform VCCs | C14: =C13 -> 25 | D14: =C14*Assumptions!$C$23+D13 -> 55.505 | E14: =D14*Assumptions!$C$23+E13 -> 92.5459 | F14: =E14*Assumptions!$C$23+F13 -> 137.28213 | G14: =F14*Assumptions!$C$23+G13 -> 191.01941
B15: New sub-funds | C15: =C14*Assumptions!F$31 -> 15 | D15: =D14*Assumptions!F$31 -> 33.303 | E15: =E14*Assumptions!F$31 -> 55.52754 | F15: =F14*Assumptions!F$31 -> 82.369279 | G15: =G14*Assumptions!F$31 -> 114.61165
B16: White-label firms | C16: =Assumptions!F$32 -> 3 | D16: =Assumptions!F$32+(Assumptions!F$33-Assumptions!F$32)*1/4 -> 7.25 | E16: =Assumptions!F$32+(Assumptions!F$33-Assumptions!F$32)*2/4 -> 11.5 | F16: =Assumptions!F$32+(Assumptions!F$33-Assumptions!F$32)*3/4 -> 15.75 | G16: =Assumptions!F$33 -> 20
B17: VCC document-set revenue | C17: =C13*Assumptions!$C$13 -> 50000 | D17: =D13*Assumptions!$C$13 -> 66010 | E17: =E13*Assumptions!$C$13 -> 85182.8 | F17: =F13*Assumptions!$C$13 -> 107981.64 | G17: =G13*Assumptions!$C$13 -> 134930.98
B18: Sub-fund revenue | C18: =C15*Assumptions!$C$14 -> 7500 | D18: =D15*Assumptions!$C$14 -> 16651.5 | E18: =E15*Assumptions!$C$14 -> 27763.77 | F18: =F15*Assumptions!$C$14 -> 41184.64 | G18: =G15*Assumptions!$C$14 -> 57305.823
B19: White-label revenue | C19: =C16*Assumptions!$C$15 -> 108000 | D19: =D16*Assumptions!$C$15 -> 261000 | E19: =E16*Assumptions!$C$15 -> 414000 | F19: =F16*Assumptions!$C$15 -> 567000 | G19: =G16*Assumptions!$C$15 -> 720000
B20: Recurring orchestration revenue | C20: =C14*Assumptions!$C$16 -> 15000 | D20: =D14*Assumptions!$C$16 -> 33303 | E20: =E14*Assumptions!$C$16 -> 55527.54 | F20: =F14*Assumptions!$C$16 -> 82369.279 | G20: =G14*Assumptions!$C$16 -> 114611.65
B21: Total revenue | C21: =SUM(C17:C20) -> 180500 | D21: =SUM(D17:D20) -> 376964.5 | E21: =SUM(E17:E20) -> 582474.11 | F21: =SUM(F17:F20) -> 798535.56 | G21: =SUM(G17:G20) -> 1026848.4
B22: Marginal cost | C22: =C13*Assumptions!$C$21+C15*Assumptions!$C$22 -> 2950 | D22: =D13*Assumptions!$C$21+D15*Assumptions!$C$22 -> 4299.59 | E22: =E13*Assumptions!$C$21+E15*Assumptions!$C$22 -> 5924.9662 | F22: =F13*Assumptions!$C$21+F15*Assumptions!$C$22 -> 7870.1606 | G22: =G13*Assumptions!$C$21+G15*Assumptions!$C$22 -> 10184.898
B23: Contribution | C23: =C21-C22 -> 177550 | D23: =D21-D22 -> 372664.91 | E23: =E21-E22 -> 576549.14 | F23: =F21-F22 -> 790665.4 | G23: =G21-G22 -> 1016663.6
B24: Fixed opex | C24: =Assumptions!$C$19 -> 450000 | D24: =C24*(1+Assumptions!$C$20) -> 504000 | E24: =D24*(1+Assumptions!$C$20) -> 564480 | F24: =E24*(1+Assumptions!$C$20) -> 632217.6 | G24: =F24*(1+Assumptions!$C$20) -> 708083.71
B25: EBITDA | C25: =C23-C24 -> -272450 | D25: =D23-D24 -> -131335.09 | E25: =E23-E24 -> 12069.144 | F25: =F23-F24 -> 158447.8 | G25: =G23-G24 -> 308579.84
B26: EBITDA margin | C26: =IF(C21=0,0,C25/C21) -> -1.5094183 | D26: =IF(D21=0,0,D25/D21) -> -0.34840175 | E26: =IF(E21=0,0,E25/E21) -> 0.020720481 | F26: =IF(F21=0,0,F25/F21) -> 0.19842298 | G26: =IF(G21=0,0,G25/G21) -> 0.30051157
B28: Cumulative revenue | C28: =C21 -> 180500 | D28: =C28+D21 -> 557464.5 | E28: =D28+E21 -> 1139938.6 | F28: =E28+F21 -> 1938474.2 | G28: =F28+G21 -> 2965322.6
B29: Cumulative EBITDA | C29: =C25 -> -272450 | D29: =C29+D25 -> -403785.09 | E29: =D29+E25 -> -391715.95 | F29: =E29+F25 -> -233268.14 | G29: =F29+G25 -> 75311.695

Sheet Scenarios
B2: SCENARIO COMPARISON
B4: SCENARIO SUMMARY
C5: Bull | D5: Base | E5: Bear
B6: 5-year revenue | C6: =SUM(C34:G34) -> 5376549.2 | D6: =SUM(C58:G58) -> 2965322.6 | E6: =SUM(C82:G82) -> 1356278.9
B7: 5-year EBITDA | C7: =SUM(C38:G38) -> 2437138.2 | D7: =SUM(C62:G62) -> 75311.695 | E7: =SUM(C86:G86) -> -1511706.6
B8: Year 5 revenue | C8: =G34 -> 1851197.6 | D8: =G58 -> 1026848.4 | E8: =G82 -> 452233.23
B9: Year 5 EBITDA margin | C9: =G39 -> 0.60298805 | D9: =G63 -> 0.30051157 | E9: =G87 -> -0.57210622
B12: POLICY CONVEXITY — BASE CASE
C13: Policy Off | D13: Policy On | E13: Delta
B14: 5-year revenue | C14: =SUM(C130:G130) -> 2627583.5 | D14: =SUM(C106:G106) -> 2965322.6 | E14: =D14-C14 -> 337739.1
B15: 5-year EBITDA | C15: =SUM(C134:G134) -> -251060.82 | D15: =SUM(C110:G110) -> 75311.695 | E15: =D15-C15 -> 326372.51
B16: Revenue upside multiple (On / Off) | D16: =IF(C14=0,0,D14/C14) -> 1.128536
B18: Bull — calculation detail
C19: Year 1 | D19: Year 2 | E19: Year 3 | F19: Year 4 | G19: Year 5
B20: Market new VCCs | C20: =Assumptions!C$27 -> 350 | D20: =C20*(1+Assumptions!C$28) -> 402.5 | E20: =D20*(1+Assumptions!C$28) -> 462.875 | F20: =E20*(1+Assumptions!C$28) -> 532.30625 | G20: =F20*(1+Assumptions!C$28) -> 612.15219
B21: Platform share of new VCCs | C21: =Assumptions!C$29 -> 0.05 | D21: =Assumptions!C$29+(Assumptions!C$30-Assumptions!C$29)*1/4 -> 0.0875 | E21: =Assumptions!C$29+(Assumptions!C$30-Assumptions!C$29)*2/4 -> 0.125 | F21: =Assumptions!C$29+(Assumptions!C$30-Assumptions!C$29)*3/4 -> 0.1625 | G21: =Assumptions!C$30 -> 0.2
B22: Platform new VCCs (organic) | C22: =C20*C21 -> 17.5 | D22: =D20*D21 -> 35.21875 | E22: =E20*E21 -> 57.859375 | F22: =F20*F21 -> 86.499766 | G22: =G20*G21 -> 122.43044
B23: Conversion eligible (start) | C23: =Assumptions!C$34 -> 12000 | D23: =C23-C24 -> 11640 | E23: =D23-D24 -> 11290.8 | F23: =E23-E24 -> 10952.076 | G23: =F23-F24 -> 10623.514
B24: Conversions (policy-gated) | C24: =C23*Assumptions!C$35*Assumptions!$B$10 -> 360 | D24: =D23*Assumptions!C$35*Assumptions!$B$10 -> 349.2 | E24: =E23*Assumptions!C$35*Assumptions!$B$10 -> 338.724 | F24: =F23*Assumptions!C$35*Assumptions!$B$10 -> 328.56228 | G24: =G23*Assumptions!C$35*Assumptions!$B$10 -> 318.70541
B25: Platform conversions | C25: =C24*Assumptions!C$36 -> 43.2 | D25: =D24*Assumptions!C$36 -> 41.904 | E25: =E24*Assumptions!C$36 -> 40.64688 | F25: =F24*Assumptions!C$36 -> 39.427474 | G25: =G24*Assumptions!C$36 -> 38.244649
B26: Platform new VCCs (total) | C26: =C22+C25 -> 60.7 | D26: =D22+D25 -> 77.12275 | E26: =E22+E25 -> 98.506255 | F26: =F22+F25 -> 125.92724 | G26: =G22+G25 -> 160.67509
B27: Active platform VCCs | C27: =C26 -> 60.7 | D27: =C27*Assumptions!$C$23+D26 -> 131.75275 | E27: =D27*Assumptions!$C$23+E26 -> 217.08373 | F27: =E27*Assumptions!$C$23+F26 -> 321.3026 | G27: =F27*Assumptions!$C$23+G26 -> 449.84742
B28: New sub-funds | C28: =C27*Assumptions!C$31 -> 48.56 | D28: =D27*Assumptions!C$31 -> 105.4022 | E28: =E27*Assumptions!C$31 -> 173.66698 | F28: =F27*Assumptions!C$31 -> 257.04208 | G28: =G27*Assumptions!C$31 -> 359.87794
B29: White-label firms | C29: =Assumptions!C$32 -> 5 | D29: =Assumptions!C$32+(Assumptions!C$33-Assumptions!C$32)*1/4 -> 11.25 | E29: =Assumptions!C$32+(Assumptions!C$33-Assumptions!C$32)*2/4 -> 17.5 | F29: =Assumptions!C$32+(Assumptions!C$33-Assumptions!C$32)*3/4 -> 23.75 | G29: =Assumptions!C$33 -> 30
B30: VCC document-set revenue | C30: =C26*Assumptions!$C$13 -> 121400 | D30: =D26*Assumptions!$C$13 -> 154245.5 | E30: =E26*Assumptions!$C$13 -> 197012.51 | F30: =F26*Assumptions!$C$13 -> 251854.48 | G30: =G26*Assumptions!$C$13 -> 321350.17
B31: Sub-fund revenue | C31: =C28*Assumptions!$C$14 -> 24280 | D31: =D28*Assumptions!$C$14 -> 52701.1 | E31: =E28*Assumptions!$C$14 -> 86833.492 | F31: =F28*Assumptions!$C$14 -> 128521.04 | G31: =G28*Assumptions!$C$14 -> 179938.97
B32: White-label revenue | C32: =C29*Assumptions!$C$15 -> 180000 | D32: =D29*Assumptions!$C$15 -> 405000 | E32: =E29*Assumptions!$C$15 -> 630000 | F32: =F29*Assumptions!$C$15 -> 855000 | G32: =G29*Assumptions!$C$15 -> 1080000
B33: Recurring orchestration revenue | C33: =C27*Assumptions!$C$16 -> 36420 | D33: =D27*Assumptions!$C$16 -> 79051.65 | E33: =E27*Assumptions!$C$16 -> 130250.24 | F33: =F27*Assumptions!$C$16 -> 192781.56 | G33: =G27*Assumptions!$C$16 -> 269908.45
B34: Total revenue | C34: =SUM(C30:C33) -> 362100 | D34: =SUM(D30:D33) -> 690998.25 | E34: =SUM(E30:E33) -> 1044096.2 | F34: =SUM(F30:F33) -> 1428157.1 | G34: =SUM(G30:G33) -> 1851197.6
B35: Marginal cost | C35: =C26*Assumptions!$C$21+C28*Assumptions!$C$22 -> 7526.8 | D35: =D26*Assumptions!$C$21+D28*Assumptions!$C$22 -> 10874.341 | E35: =E26*Assumptions!$C$21+E28*Assumptions!$C$22 -> 15060.635 | F35: =F26*Assumptions!$C$21+F28*Assumptions!$C$22 -> 20303.986 | G35: =G26*Assumptions!$C$21+G28*Assumptions!$C$22 -> 26863.847
B36: Contribution | C36: =C34-C35 -> 354573.2 | D36: =D34-D35 -> 680123.91 | E36: =E34-E35 -> 1029035.6 | F36: =F34-F35 -> 1407853.1 | G36: =G34-G35 -> 1824333.8
B37: Fixed opex | C37: =Assumptions!$C$19 -> 450000 | D37: =C37*(1+Assumptions!$C$20) -> 504000 | E37: =D37*(1+Assumptions!$C$20) -> 564480 | F37: =E37*(1+Assumptions!$C$20) -> 632217.6 | G37: =F37*(1+Assumptions!$C$20) -> 708083.71
B38: EBITDA | C38: =C36-C37 -> -95426.8 | D38: =D36-D37 -> 176123.91 | E38: =E36-E37 -> 464555.6 | F38: =F36-F37 -> 775635.49 | G38: =G36-G37 -> 1116250
B39: EBITDA margin | C39: =IF(C34=0,0,C38/C34) -> -0.26353714 | D39: =IF(D34=0,0,D38/D34) -> 0.25488329 | E39: =IF(E34=0,0,E38/E34) -> 0.44493562 | F39: =IF(F34=0,0,F38/F34) -> 0.54310237 | G39: =IF(G34=0,0,G38/G34) -> 0.60298805
B42: Base — calculation detail
C43: Year 1 | D43: Year 2 | E43: Year 3 | F43: Year 4 | G43: Year 5
B44: Market new VCCs | C44: =Assumptions!D$27 -> 300 | D44: =C44*(1+Assumptions!D$28) -> 330 | E44: =D44*(1+Assumptions!D$28) -> 363 | F44: =E44*(1+Assumptions!D$28) -> 399.3 | G44: =F44*(1+Assumptions!D$28) -> 439.23
B45: Platform share of new VCCs | C45: =Assumptions!D$29 -> 0.03 | D45: =Assumptions!D$29+(Assumptions!D$30-Assumptions!D$29)*1/4 -> 0.0525 | E45: =Assumptions!D$29+(Assumptions!D$30-Assumptions!D$29)*2/4 -> 0.075 | F45: =Assumptions!D$29+(Assumptions!D$30-Assumptions!D$29)*3/4 -> 0.0975 | G45: =Assumptions!D$30 -> 0.12
B46: Platform new VCCs (organic) | C46: =C44*C45 -> 9 | D46: =D44*D45 -> 17.325 | E46: =E44*E45 -> 27.225 | F46: =F44*F45 -> 38.93175 | G46: =G44*G45 -> 52.7076
B47: Conversion eligible (start) | C47: =Assumptions!D$34 -> 10000 | D47: =C47-C48 -> 9800 | E47: =D47-D48 -> 9604 | F47: =E47-E48 -> 9411.92 | G47: =F47-F48 -> 9223.6816
...

Sheet Dashboard
B2: DASHBOARD
B3: =CONCATENATE("Active: ",Assumptions!B6," scenario, Policy ",Assumptions!B8) -> Active: Base scenario, Policy On
B5: HEADLINE (ACTIVE SCENARIO)
B6: 5-year revenue | C6: =SUM(Model!C21:G21) -> 2965322.6
B7: 5-year EBITDA | C7: =SUM(Model!C25:G25) -> 75311.695
B8: Year 5 revenue | C8: =Model!G21 -> 1026848.4
B9: Year 5 EBITDA | C9: =Model!G25 -> 308579.84
B10: Year 5 EBITDA margin | C10: =Model!G26 -> 0.30051157
B12: SCENARIO COMPARISON
C13: =Scenarios!C5 -> Bull | D13: =Scenarios!D5 -> Base | E13: =Scenarios!E5 -> Bear
B14: 5-year revenue | C14: =Scenarios!C6 -> 5376549.2 | D14: =Scenarios!D6 -> 2965322.6 | E14: =Scenarios!E6 -> 1356278.9
B15: 5-year EBITDA | C15: =Scenarios!C7 -> 2437138.2 | D15: =Scenarios!D7 -> 75311.695 | E15: =Scenarios!E7 -> -1511706.6
B16: Year 5 revenue | C16: =Scenarios!C8 -> 1851197.6 | D16: =Scenarios!D8 -> 1026848.4 | E16: =Scenarios!E8 -> 452233.23
C18: Year 1 | D18: Year 2 | E18: Year 3 | F18: Year 4 | G18: Year 5
B19: Revenue by year (chart data)
B20: Bull | C20: =Scenarios!C34 -> 362100 | D20: =Scenarios!D34 -> 690998.25 | E20: =Scenarios!E34 -> 1044096.2 | F20: =Scenarios!F34 -> 1428157.1 | G20: =Scenarios!G34 -> 1851197.6
B21: Base | C21: =Scenarios!C58 -> 180500 | D21: =Scenarios!D58 -> 376964.5 | E21: =Scenarios!E58 -> 582474.11 | F21: =Scenarios!F58 -> 798535.56 | G21: =Scenarios!G58 -> 1026848.4
B22: Bear | C22: =Scenarios!C82 -> 94960 | D22: =Scenarios!D82 -> 180824.4 | E22: =Scenarios!E82 -> 268916.26 | F22: =Scenarios!F82 -> 359345.01 | G22: =Scenarios!G82 -> 452233.23
